[2023-10-20 12:18:23,450] {taskinstance.py:1179} INFO - Dependencies all met for <TaskInstance: vacancy_etl.load_data scheduled__2023-10-20T12:16:00+00:00 [queued]>
[2023-10-20 12:18:23,466] {taskinstance.py:1179} INFO - Dependencies all met for <TaskInstance: vacancy_etl.load_data scheduled__2023-10-20T12:16:00+00:00 [queued]>
[2023-10-20 12:18:23,467] {taskinstance.py:1376} INFO - 
--------------------------------------------------------------------------------
[2023-10-20 12:18:23,468] {taskinstance.py:1377} INFO - Starting attempt 1 of 1
[2023-10-20 12:18:23,469] {taskinstance.py:1378} INFO - 
--------------------------------------------------------------------------------
[2023-10-20 12:18:23,494] {taskinstance.py:1397} INFO - Executing <Task(PythonOperator): load_data> on 2023-10-20 12:16:00+00:00
[2023-10-20 12:18:23,501] {standard_task_runner.py:52} INFO - Started process 398 to run task
[2023-10-20 12:18:23,507] {standard_task_runner.py:79} INFO - Running: ['***', 'tasks', 'run', 'vacancy_etl', 'load_data', 'scheduled__2023-10-20T12:16:00+00:00', '--job-id', '17', '--raw', '--subdir', 'DAGS_FOLDER/test.py', '--cfg-path', '/tmp/tmpzrulzho2', '--error-file', '/tmp/tmpsr7emdnx']
[2023-10-20 12:18:23,508] {standard_task_runner.py:80} INFO - Job 17: Subtask load_data
[2023-10-20 12:18:23,601] {task_command.py:371} INFO - Running <TaskInstance: vacancy_etl.load_data scheduled__2023-10-20T12:16:00+00:00 [running]> on host 0fa47167aae4
[2023-10-20 12:18:23,805] {taskinstance.py:1591} INFO - Exporting the following env vars:
AIRFLOW_CTX_DAG_OWNER=***
AIRFLOW_CTX_DAG_ID=vacancy_etl
AIRFLOW_CTX_TASK_ID=load_data
AIRFLOW_CTX_EXECUTION_DATE=2023-10-20T12:16:00+00:00
AIRFLOW_CTX_TRY_NUMBER=1
AIRFLOW_CTX_DAG_RUN_ID=scheduled__2023-10-20T12:16:00+00:00
[2023-10-20 12:18:23,825] {base.py:68} INFO - Using connection ID 'my_db_conn' for task execution.
[2023-10-20 12:18:23,850] {taskinstance.py:1909} ERROR - Task failed with exception
Traceback (most recent call last):
  File "/home/airflow/.local/lib/python3.7/site-packages/airflow/operators/python.py", line 171, in execute
    return_value = self.execute_callable()
  File "/home/airflow/.local/lib/python3.7/site-packages/airflow/operators/python.py", line 189, in execute_callable
    return self.python_callable(*self.op_args, **self.op_kwargs)
  File "/opt/airflow/dags/test.py", line 19, in insert_db
    cur = conn.cursor()
AttributeError: 'NoneType' object has no attribute 'cursor'
[2023-10-20 12:18:23,876] {taskinstance.py:1420} INFO - Marking task as FAILED. dag_id=vacancy_etl, task_id=load_data, execution_date=20231020T121600, start_date=20231020T121823, end_date=20231020T121823
[2023-10-20 12:18:23,899] {standard_task_runner.py:97} ERROR - Failed to execute job 17 for task load_data ('NoneType' object has no attribute 'cursor'; 398)
[2023-10-20 12:18:23,919] {local_task_job.py:156} INFO - Task exited with return code 1
[2023-10-20 12:18:23,982] {local_task_job.py:273} INFO - 0 downstream tasks scheduled from follow-on schedule check
