[2023-10-20 12:22:01,807] {taskinstance.py:1179} INFO - Dependencies all met for <TaskInstance: vacancy_etl.load_data scheduled__2023-10-20T12:21:00+00:00 [queued]>
[2023-10-20 12:22:01,830] {taskinstance.py:1179} INFO - Dependencies all met for <TaskInstance: vacancy_etl.load_data scheduled__2023-10-20T12:21:00+00:00 [queued]>
[2023-10-20 12:22:01,831] {taskinstance.py:1376} INFO - 
--------------------------------------------------------------------------------
[2023-10-20 12:22:01,832] {taskinstance.py:1377} INFO - Starting attempt 1 of 1
[2023-10-20 12:22:01,834] {taskinstance.py:1378} INFO - 
--------------------------------------------------------------------------------
[2023-10-20 12:22:01,872] {taskinstance.py:1397} INFO - Executing <Task(PythonOperator): load_data> on 2023-10-20 12:21:00+00:00
[2023-10-20 12:22:01,882] {standard_task_runner.py:52} INFO - Started process 565 to run task
[2023-10-20 12:22:01,887] {standard_task_runner.py:79} INFO - Running: ['***', 'tasks', 'run', 'vacancy_etl', 'load_data', 'scheduled__2023-10-20T12:21:00+00:00', '--job-id', '23', '--raw', '--subdir', 'DAGS_FOLDER/test.py', '--cfg-path', '/tmp/tmplhb0casq', '--error-file', '/tmp/tmpemvvawug']
[2023-10-20 12:22:01,888] {standard_task_runner.py:80} INFO - Job 23: Subtask load_data
[2023-10-20 12:22:02,043] {task_command.py:371} INFO - Running <TaskInstance: vacancy_etl.load_data scheduled__2023-10-20T12:21:00+00:00 [running]> on host 0fa47167aae4
[2023-10-20 12:22:02,164] {taskinstance.py:1591} INFO - Exporting the following env vars:
AIRFLOW_CTX_DAG_OWNER=***
AIRFLOW_CTX_DAG_ID=vacancy_etl
AIRFLOW_CTX_TASK_ID=load_data
AIRFLOW_CTX_EXECUTION_DATE=2023-10-20T12:21:00+00:00
AIRFLOW_CTX_TRY_NUMBER=1
AIRFLOW_CTX_DAG_RUN_ID=scheduled__2023-10-20T12:21:00+00:00
[2023-10-20 12:22:02,180] {base.py:68} INFO - Using connection ID 'my_db_conn' for task execution.
[2023-10-20 12:22:02,207] {taskinstance.py:1909} ERROR - Task failed with exception
Traceback (most recent call last):
  File "/home/airflow/.local/lib/python3.7/site-packages/airflow/operators/python.py", line 171, in execute
    return_value = self.execute_callable()
  File "/home/airflow/.local/lib/python3.7/site-packages/airflow/operators/python.py", line 189, in execute_callable
    return self.python_callable(*self.op_args, **self.op_kwargs)
  File "/opt/airflow/dags/test.py", line 19, in insert_db
    cur = conn.cursor()
AttributeError: 'NoneType' object has no attribute 'cursor'
[2023-10-20 12:22:02,231] {taskinstance.py:1420} INFO - Marking task as FAILED. dag_id=vacancy_etl, task_id=load_data, execution_date=20231020T122100, start_date=20231020T122201, end_date=20231020T122202
[2023-10-20 12:22:02,254] {standard_task_runner.py:97} ERROR - Failed to execute job 23 for task load_data ('NoneType' object has no attribute 'cursor'; 565)
[2023-10-20 12:22:02,301] {local_task_job.py:156} INFO - Task exited with return code 1
[2023-10-20 12:22:02,353] {local_task_job.py:273} INFO - 0 downstream tasks scheduled from follow-on schedule check
