[2023-11-18 15:13:15,379] {taskinstance.py:1179} INFO - Dependencies all met for <TaskInstance: etl_hh.load_staging_layer manual__2023-11-18T15:13:11.843656+00:00 [queued]>
[2023-11-18 15:13:15,405] {taskinstance.py:1179} INFO - Dependencies all met for <TaskInstance: etl_hh.load_staging_layer manual__2023-11-18T15:13:11.843656+00:00 [queued]>
[2023-11-18 15:13:15,406] {taskinstance.py:1376} INFO - 
--------------------------------------------------------------------------------
[2023-11-18 15:13:15,407] {taskinstance.py:1377} INFO - Starting attempt 1 of 2
[2023-11-18 15:13:15,408] {taskinstance.py:1378} INFO - 
--------------------------------------------------------------------------------
[2023-11-18 15:13:15,443] {taskinstance.py:1397} INFO - Executing <Task(PythonOperator): load_staging_layer> on 2023-11-18 15:13:11.843656+00:00
[2023-11-18 15:13:15,454] {standard_task_runner.py:52} INFO - Started process 5549 to run task
[2023-11-18 15:13:15,459] {standard_task_runner.py:79} INFO - Running: ['***', 'tasks', 'run', 'etl_hh', 'load_staging_layer', 'manual__2023-11-18T15:13:11.843656+00:00', '--job-id', '85', '--raw', '--subdir', 'DAGS_FOLDER/pipeline.py', '--cfg-path', '/tmp/tmp7owh68ue', '--error-file', '/tmp/tmpsoev1y_9']
[2023-11-18 15:13:15,461] {standard_task_runner.py:80} INFO - Job 85: Subtask load_staging_layer
[2023-11-18 15:13:15,613] {task_command.py:371} INFO - Running <TaskInstance: etl_hh.load_staging_layer manual__2023-11-18T15:13:11.843656+00:00 [running]> on host 2e176173f0f7
[2023-11-18 15:13:15,884] {taskinstance.py:1591} INFO - Exporting the following env vars:
AIRFLOW_CTX_DAG_OWNER=***
AIRFLOW_CTX_DAG_ID=etl_hh
AIRFLOW_CTX_TASK_ID=load_staging_layer
AIRFLOW_CTX_EXECUTION_DATE=2023-11-18T15:13:11.843656+00:00
AIRFLOW_CTX_TRY_NUMBER=1
AIRFLOW_CTX_DAG_RUN_ID=manual__2023-11-18T15:13:11.843656+00:00
[2023-11-18 15:13:15,899] {taskinstance.py:1909} ERROR - Task failed with exception
Traceback (most recent call last):
  File "/home/airflow/.local/lib/python3.7/site-packages/airflow/operators/python.py", line 171, in execute
    return_value = self.execute_callable()
  File "/home/airflow/.local/lib/python3.7/site-packages/airflow/operators/python.py", line 189, in execute_callable
    return self.python_callable(*self.op_args, **self.op_kwargs)
  File "/opt/airflow/dags/pipeline.py", line 129, in load_data
    data = get_vacancy()
  File "/opt/airflow/dags/pipeline.py", line 94, in get_vacancy
    if not check_db_result():
  File "/opt/airflow/dags/pipeline.py", line 87, in check_db_result
    cursor.execute(sql)
psycopg2.errors.UndefinedTable: relation "row_layer.vacancy" does not exist
LINE 1: SELECT id FROM row_layer.vacancy LIMIT 1
                       ^

[2023-11-18 15:13:15,936] {taskinstance.py:1420} INFO - Marking task as UP_FOR_RETRY. dag_id=etl_hh, task_id=load_staging_layer, execution_date=20231118T151311, start_date=20231118T151315, end_date=20231118T151315
[2023-11-18 15:13:15,990] {standard_task_runner.py:97} ERROR - Failed to execute job 85 for task load_staging_layer (relation "row_layer.vacancy" does not exist
LINE 1: SELECT id FROM row_layer.vacancy LIMIT 1
                       ^
; 5549)
[2023-11-18 15:13:16,038] {local_task_job.py:156} INFO - Task exited with return code 1
[2023-11-18 15:13:16,143] {local_task_job.py:273} INFO - 0 downstream tasks scheduled from follow-on schedule check
