[2023-11-16 09:53:16,064] {taskinstance.py:1179} INFO - Dependencies all met for <TaskInstance: etl_hh.load_row_layer manual__2023-11-16T09:53:13.875196+00:00 [queued]>
[2023-11-16 09:53:16,084] {taskinstance.py:1179} INFO - Dependencies all met for <TaskInstance: etl_hh.load_row_layer manual__2023-11-16T09:53:13.875196+00:00 [queued]>
[2023-11-16 09:53:16,085] {taskinstance.py:1376} INFO - 
--------------------------------------------------------------------------------
[2023-11-16 09:53:16,086] {taskinstance.py:1377} INFO - Starting attempt 1 of 2
[2023-11-16 09:53:16,086] {taskinstance.py:1378} INFO - 
--------------------------------------------------------------------------------
[2023-11-16 09:53:16,111] {taskinstance.py:1397} INFO - Executing <Task(PythonOperator): load_row_layer> on 2023-11-16 09:53:13.875196+00:00
[2023-11-16 09:53:16,120] {standard_task_runner.py:52} INFO - Started process 2887 to run task
[2023-11-16 09:53:16,123] {standard_task_runner.py:79} INFO - Running: ['***', 'tasks', 'run', 'etl_hh', 'load_row_layer', 'manual__2023-11-16T09:53:13.875196+00:00', '--job-id', '69', '--raw', '--subdir', 'DAGS_FOLDER/pipeline.py', '--cfg-path', '/tmp/tmpkhsftpca', '--error-file', '/tmp/tmpciuazsoy']
[2023-11-16 09:53:16,123] {standard_task_runner.py:80} INFO - Job 69: Subtask load_row_layer
[2023-11-16 09:53:16,214] {task_command.py:371} INFO - Running <TaskInstance: etl_hh.load_row_layer manual__2023-11-16T09:53:13.875196+00:00 [running]> on host 2ee932ffea3c
[2023-11-16 09:53:16,346] {taskinstance.py:1591} INFO - Exporting the following env vars:
AIRFLOW_CTX_DAG_OWNER=***
AIRFLOW_CTX_DAG_ID=etl_hh
AIRFLOW_CTX_TASK_ID=load_row_layer
AIRFLOW_CTX_EXECUTION_DATE=2023-11-16T09:53:13.875196+00:00
AIRFLOW_CTX_TRY_NUMBER=1
AIRFLOW_CTX_DAG_RUN_ID=manual__2023-11-16T09:53:13.875196+00:00
[2023-11-16 09:53:16,360] {taskinstance.py:1909} ERROR - Task failed with exception
Traceback (most recent call last):
  File "/home/airflow/.local/lib/python3.7/site-packages/airflow/operators/python.py", line 171, in execute
    return_value = self.execute_callable()
  File "/home/airflow/.local/lib/python3.7/site-packages/airflow/operators/python.py", line 189, in execute_callable
    return self.python_callable(*self.op_args, **self.op_kwargs)
  File "/opt/airflow/dags/pipeline.py", line 104, in load_data
    data = get_vacancy()
  File "/opt/airflow/dags/pipeline.py", line 74, in get_vacancy
    for page in range(0, get_hh(filter, 0, period)[0] + 1):
  File "/opt/airflow/dags/pipeline.py", line 51, in get_hh
    r = requests.get(url, params=params)
  File "/home/airflow/.local/lib/python3.7/site-packages/requests/api.py", line 73, in get
    return request("get", url, params=params, **kwargs)
  File "/home/airflow/.local/lib/python3.7/site-packages/requests/api.py", line 59, in request
    return session.request(method=method, url=url, **kwargs)
  File "/home/airflow/.local/lib/python3.7/site-packages/requests/sessions.py", line 573, in request
    prep = self.prepare_request(req)
  File "/home/airflow/.local/lib/python3.7/site-packages/requests/sessions.py", line 496, in prepare_request
    hooks=merge_hooks(request.hooks, self.hooks),
  File "/home/airflow/.local/lib/python3.7/site-packages/requests/models.py", line 368, in prepare
    self.prepare_url(url, params)
  File "/home/airflow/.local/lib/python3.7/site-packages/requests/models.py", line 474, in prepare_url
    enc_params = self._encode_params(params)
  File "/home/airflow/.local/lib/python3.7/site-packages/requests/models.py", line 124, in _encode_params
    for v in vs:
TypeError: 'type' object is not iterable
[2023-11-16 09:53:16,384] {taskinstance.py:1420} INFO - Marking task as UP_FOR_RETRY. dag_id=etl_hh, task_id=load_row_layer, execution_date=20231116T095313, start_date=20231116T095316, end_date=20231116T095316
[2023-11-16 09:53:16,406] {standard_task_runner.py:97} ERROR - Failed to execute job 69 for task load_row_layer ('type' object is not iterable; 2887)
[2023-11-16 09:53:16,460] {local_task_job.py:156} INFO - Task exited with return code 1
[2023-11-16 09:53:16,516] {local_task_job.py:273} INFO - 0 downstream tasks scheduled from follow-on schedule check
