[2023-11-16 10:30:58,867] {taskinstance.py:1179} INFO - Dependencies all met for <TaskInstance: etl_hh.load_row_layer manual__2023-11-16T10:29:55.537272+00:00 [queued]>
[2023-11-16 10:30:58,888] {taskinstance.py:1179} INFO - Dependencies all met for <TaskInstance: etl_hh.load_row_layer manual__2023-11-16T10:29:55.537272+00:00 [queued]>
[2023-11-16 10:30:58,889] {taskinstance.py:1376} INFO - 
--------------------------------------------------------------------------------
[2023-11-16 10:30:58,891] {taskinstance.py:1377} INFO - Starting attempt 2 of 2
[2023-11-16 10:30:58,893] {taskinstance.py:1378} INFO - 
--------------------------------------------------------------------------------
[2023-11-16 10:30:58,923] {taskinstance.py:1397} INFO - Executing <Task(PythonOperator): load_row_layer> on 2023-11-16 10:29:55.537272+00:00
[2023-11-16 10:30:58,930] {standard_task_runner.py:52} INFO - Started process 4534 to run task
[2023-11-16 10:30:58,933] {standard_task_runner.py:79} INFO - Running: ['***', 'tasks', 'run', 'etl_hh', 'load_row_layer', 'manual__2023-11-16T10:29:55.537272+00:00', '--job-id', '76', '--raw', '--subdir', 'DAGS_FOLDER/pipeline.py', '--cfg-path', '/tmp/tmpnbc4upsn', '--error-file', '/tmp/tmp5ecq4fop']
[2023-11-16 10:30:58,934] {standard_task_runner.py:80} INFO - Job 76: Subtask load_row_layer
[2023-11-16 10:30:59,026] {task_command.py:371} INFO - Running <TaskInstance: etl_hh.load_row_layer manual__2023-11-16T10:29:55.537272+00:00 [running]> on host 2ee932ffea3c
[2023-11-16 10:30:59,137] {taskinstance.py:1591} INFO - Exporting the following env vars:
AIRFLOW_CTX_DAG_OWNER=***
AIRFLOW_CTX_DAG_ID=etl_hh
AIRFLOW_CTX_TASK_ID=load_row_layer
AIRFLOW_CTX_EXECUTION_DATE=2023-11-16T10:29:55.537272+00:00
AIRFLOW_CTX_TRY_NUMBER=2
AIRFLOW_CTX_DAG_RUN_ID=manual__2023-11-16T10:29:55.537272+00:00
[2023-11-16 10:30:59,139] {taskinstance.py:1909} ERROR - Task failed with exception
Traceback (most recent call last):
  File "/home/airflow/.local/lib/python3.7/site-packages/airflow/operators/python.py", line 171, in execute
    return_value = self.execute_callable()
  File "/home/airflow/.local/lib/python3.7/site-packages/airflow/operators/python.py", line 189, in execute_callable
    return self.python_callable(*self.op_args, **self.op_kwargs)
  File "/opt/airflow/dags/pipeline.py", line 136, in test
    cursor.execute(sql, row)
IndexError: list index out of range
[2023-11-16 10:30:59,157] {taskinstance.py:1420} INFO - Marking task as FAILED. dag_id=etl_hh, task_id=load_row_layer, execution_date=20231116T102955, start_date=20231116T103058, end_date=20231116T103059
[2023-11-16 10:30:59,178] {standard_task_runner.py:97} ERROR - Failed to execute job 76 for task load_row_layer (list index out of range; 4534)
[2023-11-16 10:30:59,226] {local_task_job.py:156} INFO - Task exited with return code 1
[2023-11-16 10:30:59,279] {local_task_job.py:273} INFO - 0 downstream tasks scheduled from follow-on schedule check
