[2023-11-16 10:29:57,758] {taskinstance.py:1179} INFO - Dependencies all met for <TaskInstance: etl_hh.load_row_layer manual__2023-11-16T10:29:55.537272+00:00 [queued]>
[2023-11-16 10:29:57,778] {taskinstance.py:1179} INFO - Dependencies all met for <TaskInstance: etl_hh.load_row_layer manual__2023-11-16T10:29:55.537272+00:00 [queued]>
[2023-11-16 10:29:57,779] {taskinstance.py:1376} INFO - 
--------------------------------------------------------------------------------
[2023-11-16 10:29:57,780] {taskinstance.py:1377} INFO - Starting attempt 1 of 2
[2023-11-16 10:29:57,780] {taskinstance.py:1378} INFO - 
--------------------------------------------------------------------------------
[2023-11-16 10:29:57,801] {taskinstance.py:1397} INFO - Executing <Task(PythonOperator): load_row_layer> on 2023-11-16 10:29:55.537272+00:00
[2023-11-16 10:29:57,808] {standard_task_runner.py:52} INFO - Started process 4486 to run task
[2023-11-16 10:29:57,811] {standard_task_runner.py:79} INFO - Running: ['***', 'tasks', 'run', 'etl_hh', 'load_row_layer', 'manual__2023-11-16T10:29:55.537272+00:00', '--job-id', '75', '--raw', '--subdir', 'DAGS_FOLDER/pipeline.py', '--cfg-path', '/tmp/tmpktc485y0', '--error-file', '/tmp/tmp70dfinx2']
[2023-11-16 10:29:57,812] {standard_task_runner.py:80} INFO - Job 75: Subtask load_row_layer
[2023-11-16 10:29:57,900] {task_command.py:371} INFO - Running <TaskInstance: etl_hh.load_row_layer manual__2023-11-16T10:29:55.537272+00:00 [running]> on host 2ee932ffea3c
[2023-11-16 10:29:58,021] {taskinstance.py:1591} INFO - Exporting the following env vars:
AIRFLOW_CTX_DAG_OWNER=***
AIRFLOW_CTX_DAG_ID=etl_hh
AIRFLOW_CTX_TASK_ID=load_row_layer
AIRFLOW_CTX_EXECUTION_DATE=2023-11-16T10:29:55.537272+00:00
AIRFLOW_CTX_TRY_NUMBER=1
AIRFLOW_CTX_DAG_RUN_ID=manual__2023-11-16T10:29:55.537272+00:00
[2023-11-16 10:29:58,024] {taskinstance.py:1909} ERROR - Task failed with exception
Traceback (most recent call last):
  File "/home/airflow/.local/lib/python3.7/site-packages/airflow/operators/python.py", line 171, in execute
    return_value = self.execute_callable()
  File "/home/airflow/.local/lib/python3.7/site-packages/airflow/operators/python.py", line 189, in execute_callable
    return self.python_callable(*self.op_args, **self.op_kwargs)
  File "/opt/airflow/dags/pipeline.py", line 136, in test
    cursor.execute(sql, row)
IndexError: list index out of range
[2023-11-16 10:29:58,044] {taskinstance.py:1420} INFO - Marking task as UP_FOR_RETRY. dag_id=etl_hh, task_id=load_row_layer, execution_date=20231116T102955, start_date=20231116T102957, end_date=20231116T102958
[2023-11-16 10:29:58,065] {standard_task_runner.py:97} ERROR - Failed to execute job 75 for task load_row_layer (list index out of range; 4486)
[2023-11-16 10:29:58,104] {local_task_job.py:156} INFO - Task exited with return code 1
[2023-11-16 10:29:58,162] {local_task_job.py:273} INFO - 0 downstream tasks scheduled from follow-on schedule check
