[2023-11-16 10:13:22,719] {taskinstance.py:1179} INFO - Dependencies all met for <TaskInstance: etl_hh.load_row_layer manual__2023-11-16T10:13:20.930274+00:00 [queued]>
[2023-11-16 10:13:22,744] {taskinstance.py:1179} INFO - Dependencies all met for <TaskInstance: etl_hh.load_row_layer manual__2023-11-16T10:13:20.930274+00:00 [queued]>
[2023-11-16 10:13:22,745] {taskinstance.py:1376} INFO - 
--------------------------------------------------------------------------------
[2023-11-16 10:13:22,746] {taskinstance.py:1377} INFO - Starting attempt 1 of 2
[2023-11-16 10:13:22,747] {taskinstance.py:1378} INFO - 
--------------------------------------------------------------------------------
[2023-11-16 10:13:22,783] {taskinstance.py:1397} INFO - Executing <Task(PythonOperator): load_row_layer> on 2023-11-16 10:13:20.930274+00:00
[2023-11-16 10:13:22,792] {standard_task_runner.py:52} INFO - Started process 3772 to run task
[2023-11-16 10:13:22,796] {standard_task_runner.py:79} INFO - Running: ['***', 'tasks', 'run', 'etl_hh', 'load_row_layer', 'manual__2023-11-16T10:13:20.930274+00:00', '--job-id', '73', '--raw', '--subdir', 'DAGS_FOLDER/pipeline.py', '--cfg-path', '/tmp/tmpk09fv1a8', '--error-file', '/tmp/tmp2fsgf76x']
[2023-11-16 10:13:22,798] {standard_task_runner.py:80} INFO - Job 73: Subtask load_row_layer
[2023-11-16 10:13:22,920] {task_command.py:371} INFO - Running <TaskInstance: etl_hh.load_row_layer manual__2023-11-16T10:13:20.930274+00:00 [running]> on host 2ee932ffea3c
[2023-11-16 10:13:23,070] {taskinstance.py:1591} INFO - Exporting the following env vars:
AIRFLOW_CTX_DAG_OWNER=***
AIRFLOW_CTX_DAG_ID=etl_hh
AIRFLOW_CTX_TASK_ID=load_row_layer
AIRFLOW_CTX_EXECUTION_DATE=2023-11-16T10:13:20.930274+00:00
AIRFLOW_CTX_TRY_NUMBER=1
AIRFLOW_CTX_DAG_RUN_ID=manual__2023-11-16T10:13:20.930274+00:00
[2023-11-16 10:13:23,078] {taskinstance.py:1909} ERROR - Task failed with exception
Traceback (most recent call last):
  File "/home/airflow/.local/lib/python3.7/site-packages/airflow/operators/python.py", line 171, in execute
    return_value = self.execute_callable()
  File "/home/airflow/.local/lib/python3.7/site-packages/airflow/operators/python.py", line 189, in execute_callable
    return self.python_callable(*self.op_args, **self.op_kwargs)
  File "/opt/airflow/dags/pipeline.py", line 121, in load_data
    data = get_vacancy()
  File "/opt/airflow/dags/pipeline.py", line 91, in get_vacancy
    for page in range(0, get_hh(filter, 0, period)[0] + 1):
  File "/opt/airflow/dags/pipeline.py", line 68, in get_hh
    r = requests.get(url, params=params)
  File "/home/airflow/.local/lib/python3.7/site-packages/requests/api.py", line 73, in get
    return request("get", url, params=params, **kwargs)
  File "/home/airflow/.local/lib/python3.7/site-packages/requests/api.py", line 59, in request
    return session.request(method=method, url=url, **kwargs)
  File "/home/airflow/.local/lib/python3.7/site-packages/requests/sessions.py", line 573, in request
    prep = self.prepare_request(req)
  File "/home/airflow/.local/lib/python3.7/site-packages/requests/sessions.py", line 496, in prepare_request
    hooks=merge_hooks(request.hooks, self.hooks),
  File "/home/airflow/.local/lib/python3.7/site-packages/requests/models.py", line 368, in prepare
    self.prepare_url(url, params)
  File "/home/airflow/.local/lib/python3.7/site-packages/requests/models.py", line 474, in prepare_url
    enc_params = self._encode_params(params)
  File "/home/airflow/.local/lib/python3.7/site-packages/requests/models.py", line 124, in _encode_params
    for v in vs:
TypeError: 'type' object is not iterable
[2023-11-16 10:13:23,100] {taskinstance.py:1420} INFO - Marking task as UP_FOR_RETRY. dag_id=etl_hh, task_id=load_row_layer, execution_date=20231116T101320, start_date=20231116T101322, end_date=20231116T101323
[2023-11-16 10:13:23,123] {standard_task_runner.py:97} ERROR - Failed to execute job 73 for task load_row_layer ('type' object is not iterable; 3772)
[2023-11-16 10:13:23,169] {local_task_job.py:156} INFO - Task exited with return code 1
[2023-11-16 10:13:23,226] {local_task_job.py:273} INFO - 0 downstream tasks scheduled from follow-on schedule check
