[2023-11-16 11:14:13,792] {taskinstance.py:1179} INFO - Dependencies all met for <TaskInstance: etl_hh.load_row_layer manual__2023-11-16T11:13:07.882641+00:00 [queued]>
[2023-11-16 11:14:13,816] {taskinstance.py:1179} INFO - Dependencies all met for <TaskInstance: etl_hh.load_row_layer manual__2023-11-16T11:13:07.882641+00:00 [queued]>
[2023-11-16 11:14:13,817] {taskinstance.py:1376} INFO - 
--------------------------------------------------------------------------------
[2023-11-16 11:14:13,817] {taskinstance.py:1377} INFO - Starting attempt 2 of 2
[2023-11-16 11:14:13,818] {taskinstance.py:1378} INFO - 
--------------------------------------------------------------------------------
[2023-11-16 11:14:13,838] {taskinstance.py:1397} INFO - Executing <Task(PythonOperator): load_row_layer> on 2023-11-16 11:13:07.882641+00:00
[2023-11-16 11:14:13,847] {standard_task_runner.py:52} INFO - Started process 201 to run task
[2023-11-16 11:14:13,852] {standard_task_runner.py:79} INFO - Running: ['***', 'tasks', 'run', 'etl_hh', 'load_row_layer', 'manual__2023-11-16T11:13:07.882641+00:00', '--job-id', '81', '--raw', '--subdir', 'DAGS_FOLDER/pipeline.py', '--cfg-path', '/tmp/tmpiwlqdima', '--error-file', '/tmp/tmpiuvyo0fp']
[2023-11-16 11:14:13,853] {standard_task_runner.py:80} INFO - Job 81: Subtask load_row_layer
[2023-11-16 11:14:13,974] {task_command.py:371} INFO - Running <TaskInstance: etl_hh.load_row_layer manual__2023-11-16T11:13:07.882641+00:00 [running]> on host 724455ac2390
[2023-11-16 11:14:14,140] {taskinstance.py:1591} INFO - Exporting the following env vars:
AIRFLOW_CTX_DAG_OWNER=***
AIRFLOW_CTX_DAG_ID=etl_hh
AIRFLOW_CTX_TASK_ID=load_row_layer
AIRFLOW_CTX_EXECUTION_DATE=2023-11-16T11:13:07.882641+00:00
AIRFLOW_CTX_TRY_NUMBER=2
AIRFLOW_CTX_DAG_RUN_ID=manual__2023-11-16T11:13:07.882641+00:00
[2023-11-16 11:14:14,149] {taskinstance.py:1909} ERROR - Task failed with exception
Traceback (most recent call last):
  File "/home/airflow/.local/lib/python3.7/site-packages/airflow/operators/python.py", line 171, in execute
    return_value = self.execute_callable()
  File "/home/airflow/.local/lib/python3.7/site-packages/airflow/operators/python.py", line 189, in execute_callable
    return self.python_callable(*self.op_args, **self.op_kwargs)
  File "/opt/airflow/dags/pipeline.py", line 121, in load_data
    data = get_vacancy()
  File "/opt/airflow/dags/pipeline.py", line 91, in get_vacancy
    for page in range(0, get_hh(filter, 0, period)[0] + 1):
  File "/opt/airflow/dags/pipeline.py", line 68, in get_hh
    r = requests.get(url, params=params)
  File "/home/airflow/.local/lib/python3.7/site-packages/requests/api.py", line 73, in get
    return request("get", url, params=params, **kwargs)
  File "/home/airflow/.local/lib/python3.7/site-packages/requests/api.py", line 59, in request
    return session.request(method=method, url=url, **kwargs)
  File "/home/airflow/.local/lib/python3.7/site-packages/requests/sessions.py", line 573, in request
    prep = self.prepare_request(req)
  File "/home/airflow/.local/lib/python3.7/site-packages/requests/sessions.py", line 496, in prepare_request
    hooks=merge_hooks(request.hooks, self.hooks),
  File "/home/airflow/.local/lib/python3.7/site-packages/requests/models.py", line 368, in prepare
    self.prepare_url(url, params)
  File "/home/airflow/.local/lib/python3.7/site-packages/requests/models.py", line 474, in prepare_url
    enc_params = self._encode_params(params)
  File "/home/airflow/.local/lib/python3.7/site-packages/requests/models.py", line 124, in _encode_params
    for v in vs:
TypeError: 'type' object is not iterable
[2023-11-16 11:14:14,166] {taskinstance.py:1420} INFO - Marking task as FAILED. dag_id=etl_hh, task_id=load_row_layer, execution_date=20231116T111307, start_date=20231116T111413, end_date=20231116T111414
[2023-11-16 11:14:14,183] {standard_task_runner.py:97} ERROR - Failed to execute job 81 for task load_row_layer ('type' object is not iterable; 201)
[2023-11-16 11:14:14,224] {local_task_job.py:156} INFO - Task exited with return code 1
[2023-11-16 11:14:14,313] {local_task_job.py:273} INFO - 0 downstream tasks scheduled from follow-on schedule check
