[2023-10-20 11:57:04,323] {taskinstance.py:1179} INFO - Dependencies all met for <TaskInstance: daily_update_dag.create_data_mart manual__2023-10-20T11:57:02.187945+00:00 [queued]>
[2023-10-20 11:57:04,344] {taskinstance.py:1179} INFO - Dependencies all met for <TaskInstance: daily_update_dag.create_data_mart manual__2023-10-20T11:57:02.187945+00:00 [queued]>
[2023-10-20 11:57:04,349] {taskinstance.py:1376} INFO - 
--------------------------------------------------------------------------------
[2023-10-20 11:57:04,350] {taskinstance.py:1377} INFO - Starting attempt 1 of 1
[2023-10-20 11:57:04,351] {taskinstance.py:1378} INFO - 
--------------------------------------------------------------------------------
[2023-10-20 11:57:04,377] {taskinstance.py:1397} INFO - Executing <Task(PythonOperator): create_data_mart> on 2023-10-20 11:57:02.187945+00:00
[2023-10-20 11:57:04,432] {standard_task_runner.py:52} INFO - Started process 300 to run task
[2023-10-20 11:57:04,439] {standard_task_runner.py:79} INFO - Running: ['***', 'tasks', 'run', 'daily_update_dag', 'create_data_mart', 'manual__2023-10-20T11:57:02.187945+00:00', '--job-id', '10', '--raw', '--subdir', 'DAGS_FOLDER/init.py', '--cfg-path', '/tmp/tmpntg72ti5', '--error-file', '/tmp/tmp__rjl459']
[2023-10-20 11:57:04,445] {standard_task_runner.py:80} INFO - Job 10: Subtask create_data_mart
[2023-10-20 11:57:04,576] {task_command.py:371} INFO - Running <TaskInstance: daily_update_dag.create_data_mart manual__2023-10-20T11:57:02.187945+00:00 [running]> on host 0fa47167aae4
[2023-10-20 11:57:04,746] {taskinstance.py:1591} INFO - Exporting the following env vars:
AIRFLOW_CTX_DAG_OWNER=konstantin_a
AIRFLOW_CTX_DAG_ID=daily_update_dag
AIRFLOW_CTX_TASK_ID=create_data_mart
AIRFLOW_CTX_EXECUTION_DATE=2023-10-20T11:57:02.187945+00:00
AIRFLOW_CTX_TRY_NUMBER=1
AIRFLOW_CTX_DAG_RUN_ID=manual__2023-10-20T11:57:02.187945+00:00
[2023-10-20 11:57:04,829] {logging_mixin.py:115} INFO - Таблица data_mart создана!
[2023-10-20 11:57:04,840] {taskinstance.py:1909} ERROR - Task failed with exception
Traceback (most recent call last):
  File "/home/airflow/.local/lib/python3.7/site-packages/airflow/operators/python.py", line 171, in execute
    return_value = self.execute_callable()
  File "/home/airflow/.local/lib/python3.7/site-packages/airflow/operators/python.py", line 189, in execute_callable
    return self.python_callable(*self.op_args, **self.op_kwargs)
  File "/opt/airflow/dags/init.py", line 436, in create_data_mart
    """)
psycopg2.errors.UndefinedTable: relation "core_layer_stock_prices" does not exist
LINE 42:         FROM core_layer_stock_prices
                      ^

[2023-10-20 11:57:04,886] {taskinstance.py:1420} INFO - Marking task as FAILED. dag_id=daily_update_dag, task_id=create_data_mart, execution_date=20231020T115702, start_date=20231020T115704, end_date=20231020T115704
[2023-10-20 11:57:04,913] {standard_task_runner.py:97} ERROR - Failed to execute job 10 for task create_data_mart (relation "core_layer_stock_prices" does not exist
LINE 42:         FROM core_layer_stock_prices
                      ^
; 300)
[2023-10-20 11:57:04,937] {local_task_job.py:156} INFO - Task exited with return code 1
[2023-10-20 11:57:05,110] {local_task_job.py:273} INFO - 0 downstream tasks scheduled from follow-on schedule check
