[2023-10-20 12:20:01,690] {taskinstance.py:1179} INFO - Dependencies all met for <TaskInstance: vacancy_etl.load_data scheduled__2023-10-20T12:19:00+00:00 [queued]>
[2023-10-20 12:20:01,709] {taskinstance.py:1179} INFO - Dependencies all met for <TaskInstance: vacancy_etl.load_data scheduled__2023-10-20T12:19:00+00:00 [queued]>
[2023-10-20 12:20:01,710] {taskinstance.py:1376} INFO - 
--------------------------------------------------------------------------------
[2023-10-20 12:20:01,711] {taskinstance.py:1377} INFO - Starting attempt 1 of 1
[2023-10-20 12:20:01,712] {taskinstance.py:1378} INFO - 
--------------------------------------------------------------------------------
[2023-10-20 12:20:01,735] {taskinstance.py:1397} INFO - Executing <Task(PythonOperator): load_data> on 2023-10-20 12:19:00+00:00
[2023-10-20 12:20:01,742] {standard_task_runner.py:52} INFO - Started process 479 to run task
[2023-10-20 12:20:01,746] {standard_task_runner.py:79} INFO - Running: ['***', 'tasks', 'run', 'vacancy_etl', 'load_data', 'scheduled__2023-10-20T12:19:00+00:00', '--job-id', '21', '--raw', '--subdir', 'DAGS_FOLDER/test.py', '--cfg-path', '/tmp/tmpbdr44vef', '--error-file', '/tmp/tmpphnsv546']
[2023-10-20 12:20:01,747] {standard_task_runner.py:80} INFO - Job 21: Subtask load_data
[2023-10-20 12:20:01,854] {task_command.py:371} INFO - Running <TaskInstance: vacancy_etl.load_data scheduled__2023-10-20T12:19:00+00:00 [running]> on host 0fa47167aae4
[2023-10-20 12:20:02,000] {taskinstance.py:1591} INFO - Exporting the following env vars:
AIRFLOW_CTX_DAG_OWNER=***
AIRFLOW_CTX_DAG_ID=vacancy_etl
AIRFLOW_CTX_TASK_ID=load_data
AIRFLOW_CTX_EXECUTION_DATE=2023-10-20T12:19:00+00:00
AIRFLOW_CTX_TRY_NUMBER=1
AIRFLOW_CTX_DAG_RUN_ID=scheduled__2023-10-20T12:19:00+00:00
[2023-10-20 12:20:02,018] {base.py:68} INFO - Using connection ID 'my_db_conn' for task execution.
[2023-10-20 12:20:02,051] {taskinstance.py:1909} ERROR - Task failed with exception
Traceback (most recent call last):
  File "/home/airflow/.local/lib/python3.7/site-packages/airflow/operators/python.py", line 171, in execute
    return_value = self.execute_callable()
  File "/home/airflow/.local/lib/python3.7/site-packages/airflow/operators/python.py", line 189, in execute_callable
    return self.python_callable(*self.op_args, **self.op_kwargs)
  File "/opt/airflow/dags/test.py", line 19, in insert_db
    cur = conn.cursor()
AttributeError: 'NoneType' object has no attribute 'cursor'
[2023-10-20 12:20:02,077] {taskinstance.py:1420} INFO - Marking task as FAILED. dag_id=vacancy_etl, task_id=load_data, execution_date=20231020T121900, start_date=20231020T122001, end_date=20231020T122002
[2023-10-20 12:20:02,100] {standard_task_runner.py:97} ERROR - Failed to execute job 21 for task load_data ('NoneType' object has no attribute 'cursor'; 479)
[2023-10-20 12:20:02,119] {local_task_job.py:156} INFO - Task exited with return code 1
[2023-10-20 12:20:02,189] {local_task_job.py:273} INFO - 0 downstream tasks scheduled from follow-on schedule check
