[2023-11-18 19:37:09,490] {taskinstance.py:1179} INFO - Dependencies all met for <TaskInstance: etl_hh.load_core_dim_employer manual__2023-11-18T19:36:47.836543+00:00 [queued]>
[2023-11-18 19:37:09,516] {taskinstance.py:1179} INFO - Dependencies all met for <TaskInstance: etl_hh.load_core_dim_employer manual__2023-11-18T19:36:47.836543+00:00 [queued]>
[2023-11-18 19:37:09,517] {taskinstance.py:1376} INFO - 
--------------------------------------------------------------------------------
[2023-11-18 19:37:09,518] {taskinstance.py:1377} INFO - Starting attempt 1 of 2
[2023-11-18 19:37:09,518] {taskinstance.py:1378} INFO - 
--------------------------------------------------------------------------------
[2023-11-18 19:37:09,541] {taskinstance.py:1397} INFO - Executing <Task(PostgresOperator): load_core_dim_employer> on 2023-11-18 19:36:47.836543+00:00
[2023-11-18 19:37:09,548] {standard_task_runner.py:52} INFO - Started process 13424 to run task
[2023-11-18 19:37:09,552] {standard_task_runner.py:79} INFO - Running: ['***', 'tasks', 'run', 'etl_hh', 'load_core_dim_employer', 'manual__2023-11-18T19:36:47.836543+00:00', '--job-id', '97', '--raw', '--subdir', 'DAGS_FOLDER/pipeline.py', '--cfg-path', '/tmp/tmp_5k1nvgp', '--error-file', '/tmp/tmp9zyfzl71']
[2023-11-18 19:37:09,553] {standard_task_runner.py:80} INFO - Job 97: Subtask load_core_dim_employer
[2023-11-18 19:37:09,666] {task_command.py:371} INFO - Running <TaskInstance: etl_hh.load_core_dim_employer manual__2023-11-18T19:36:47.836543+00:00 [running]> on host 2e176173f0f7
[2023-11-18 19:37:09,799] {taskinstance.py:1591} INFO - Exporting the following env vars:
AIRFLOW_CTX_DAG_OWNER=***
AIRFLOW_CTX_DAG_ID=etl_hh
AIRFLOW_CTX_TASK_ID=load_core_dim_employer
AIRFLOW_CTX_EXECUTION_DATE=2023-11-18T19:36:47.836543+00:00
AIRFLOW_CTX_TRY_NUMBER=1
AIRFLOW_CTX_DAG_RUN_ID=manual__2023-11-18T19:36:47.836543+00:00
[2023-11-18 19:37:09,832] {taskinstance.py:1909} ERROR - Task failed with exception
Traceback (most recent call last):
  File "/home/airflow/.local/lib/python3.7/site-packages/airflow/providers/postgres/operators/postgres.py", line 92, in execute
    self.hook.run(self.sql, self.autocommit, parameters=self.parameters)
  File "/home/airflow/.local/lib/python3.7/site-packages/airflow/hooks/dbapi.py", line 204, in run
    with closing(self.get_conn()) as conn:
  File "/home/airflow/.local/lib/python3.7/site-packages/airflow/providers/postgres/hooks/postgres.py", line 86, in get_conn
    conn = deepcopy(self.connection or self.get_connection(conn_id))
  File "/home/airflow/.local/lib/python3.7/site-packages/airflow/hooks/base.py", line 67, in get_connection
    conn = Connection.get_connection_from_secrets(conn_id)
  File "/home/airflow/.local/lib/python3.7/site-packages/airflow/models/connection.py", line 430, in get_connection_from_secrets
    raise AirflowNotFoundException(f"The conn_id `{conn_id}` isn't defined")
airflow.exceptions.AirflowNotFoundException: The conn_id `me_db_conn` isn't defined
[2023-11-18 19:37:09,840] {taskinstance.py:1420} INFO - Marking task as UP_FOR_RETRY. dag_id=etl_hh, task_id=load_core_dim_employer, execution_date=20231118T193647, start_date=20231118T193709, end_date=20231118T193709
[2023-11-18 19:37:09,863] {standard_task_runner.py:97} ERROR - Failed to execute job 97 for task load_core_dim_employer (The conn_id `me_db_conn` isn't defined; 13424)
[2023-11-18 19:37:09,885] {local_task_job.py:156} INFO - Task exited with return code 1
[2023-11-18 19:37:09,978] {local_task_job.py:273} INFO - 0 downstream tasks scheduled from follow-on schedule check
